<?xml version="1.0" encoding="utf-8"?>
<!-- This URDF was automatically created by SolidWorks to URDF Exporter! Originally created by Stephen Brawner (brawner@gmail.com) 
     Commit Version: 1.6.0-4-g7f85cfe  Build Version: 1.6.7995.38578
     For more information, please see http://wiki.ros.org/sw_urdf_exporter -->
<robot
  name="RoboticArm_urdf">
  <link name="world"/>
  <joint name="base_joint" type="fixed">
    <parent link="world"/>
    <child link="base_link"/>
    <origin xyz="0 0 3.142" rpy="0.0 0.0 0.0"/>
  </joint>

  <link
    name="base_link">
    <inertial>
  <origin
    xyz="0 0 0.03"
    rpy="0 0 0" />
  <mass
    value="1.0" />
  <inertia
    ixx="0.0012"
    ixy="0.0"
    ixz="0.0"
    iyy="0.0012"
    iyz="0.0"
    izz="0.0018" />
</inertial>

    <visual>
      <origin
        xyz="0 0 0"
        rpy="0 0 0" />
      <geometry>
        <mesh
          filename="package://RoboticArm_urdf/meshes/base_link.STL" />
      </geometry>
      <material
        name="">
        <color
          rgba="1 1 1 1" />
      </material>
    </visual>
    <collision>
      <origin
        xyz="0 0 0"
        rpy="0 0 0" />
      <geometry>
        <mesh
          filename="package://RoboticArm_urdf/meshes/base_link.STL" />
      </geometry>
    </collision>
  </link>
  <link
    name="link_1">
    <inertial>
  <origin
    xyz="0.0169 0 0.01275"
    rpy="0 0 0" />
  <mass
    value="0.6" />
  <inertia
    ixx="0.00048"
    ixy="0.0"
    ixz="0.0"
    iyy="0.00048"
    iyz="0.0"
    izz="0.00078" />
</inertial>

    <visual>
      <origin
        xyz="0 0 0"
        rpy="0 0 0" />
      <geometry>
        <mesh
          filename="package://RoboticArm_urdf/meshes/link_1.STL" />
      </geometry>
      <material
        name="">
        <color
          rgba="1 1 1 1" />
      </material>
    </visual>
    <collision>
      <origin
        xyz="0 0 0"
        rpy="0 0 0" />
      <geometry>
        <mesh
          filename="package://RoboticArm_urdf/meshes/link_1.STL" />
      </geometry>
    </collision>
  </link>
  <joint
  name="joint_1"
  type="revolute">
  <origin
    xyz="0 0 0.009"
    rpy="0 0 0" />
  <parent
    link="base_link" />
  <child
    link="link_1" />
  <axis
    xyz="0 0 1" />
  <limit
    lower="-3.14159"
    upper="3.14159"
    effort="2"
    velocity="1.2" />
</joint>

  <link
    name="link_2">
    <inertial>
      <origin
        xyz="1.39648084080978 -0.364975316700641 1.05474204784036"
        rpy="0 0 0" />
      <mass
        value="0.137984774765341" />
      <inertia
        ixx="0.000431683448978738"
        ixy="3.34744173902785E-09"
        ixz="5.3958890735214E-10"
        iyy="5.6960151332206E-05"
        iyz="-9.64347346480118E-05"
        izz="0.000386802528951711" />
    </inertial>
    <visual>
      <origin
        xyz="0 0 0"
        rpy="0 0 0" />
      <geometry>
        <mesh
          filename="package://RoboticArm_urdf/meshes/link_2.STL" />
      </geometry>
      <material
        name="">
        <color
          rgba="1 1 1 1" />
      </material>
    </visual>
    <collision>
      <origin
        xyz="0 0 0"
        rpy="0 0 0" />
      <geometry>
        <mesh
          filename="package://RoboticArm_urdf/meshes/link_2.STL" />
      </geometry>
    </collision>
  </link>
  <joint name="joint_2" type="revolute">
  <origin
    xyz="0 0 0.15"
    rpy="0 0 0" />
  <parent link="link_1" />
  <child link="link_2" />
  <axis xyz="0 1 0" />
  <limit
    lower="-1.5708"
    upper="1.5708"
    effort="1.5"
    velocity="1.0" />
</joint>

  <link name="link_3">
  <inertial>
    <origin
      xyz="0 0 0.055"
      rpy="0 0 0" />
    <mass
      value="0.4" />
    <inertia
      ixx="0.000421" ixy="0.0" ixz="0.0"
      iyy="0.000421" iyz="0.0"
      izz="0.00006" />
  </inertial>

  <visual>
    <origin
      xyz="0 0 0"
      rpy="0 0 0" />
    <geometry>
      <mesh filename="package://robot_arm_urdf/meshes/link_3.STL"/>
    </geometry>
    <material name="">
      <color rgba="0.8 0.5 0.5 1.0"/>
    </material>
  </visual>

  <collision>
    <origin
      xyz="0 0 0"
      rpy="0 0 0" />
    <geometry>
      <mesh filename="package://robot_arm_urdf/meshes/link_3.STL"/>
    </geometry>
  </collision>
</link>

  <joint name="joint_3" type="revolute">
  <origin
    xyz="0 0 0.15"
    rpy="0 0 0" />
  <parent link="link_2"/>
  <child link="link_3"/>
  <axis xyz="0 1 0"/>
  <limit
    lower="-1.5708"
    upper="1.5708"
    effort="1.2"
    velocity="1.0"/>
</joint>

  <link name="link_4">
  <inertial>
    <origin xyz="0 0 0.025" rpy="0 0 0" />
    <mass value="0.4" />
    <inertia
      ixx="0.0000766" ixy="0.0" ixz="0.0"
      iyy="0.0000766" iyz="0.0"
      izz="0.0000266" />
  </inertial>

  <visual>
    <origin xyz="0 0 0" rpy="0 0 0" />
    <geometry>
      <mesh filename="package://robot_arm_urdf/meshes/link_4.STL"/>
    </geometry>
    <material name="">
      <color rgba="1 1 1 1"/>
    </material>
  </visual>

  <collision>
    <origin xyz="0 0 0" rpy="0 0 0" />
    <geometry>
      <mesh filename="package://robot_arm_urdf/meshes/link_4.STL"/>
    </geometry>
  </collision>
</link>

  <joint name="joint_4" type="revolute">
  <origin xyz="0 0 0.11" rpy="0 0 0"/>
  <parent link="link_3"/>
  <child link="link_4"/>
  <axis xyz="0 0 1"/>
  <limit lower="-1.5708" upper="1.5708" effort="1.2" velocity="1.0"/>
</joint>
<link name="link_5">
  <inertial>
    <origin
      xyz="0 0 0.03"
      rpy="0 0 0" />
    <mass
      value="0.2" />
    <inertia
      ixx="0.00005"
      ixy="0.0"
      ixz="0.0"
      iyy="0.00005"
      iyz="0.0"
      izz="0.00007" />
  </inertial>

  <visual>
    <origin
      xyz="0 0 0"
      rpy="0 0 0" />
    <geometry>
      <mesh
        filename="package://ReadyRoboticArm_1/meshes/link_5.STL" />
    </geometry>
    <material name="">
      <color rgba="1 1 1 1" />
    </material>
  </visual>

  <collision>
    <origin
      xyz="0 0 0"
      rpy="0 0 0" />
    <geometry>
      <mesh
        filename="package://ReadyRoboticArm_1/meshes/link_5.STL" />
    </geometry>
  </collision>
</link>

 <joint name="joint_5" type="revolute">
  <origin
    xyz="0 0 0.05"
    rpy="0 0 0" />
  <parent link="link_4" />
  <child link="link_5" />
  <axis
    xyz="0 1 0" />
  <limit
    lower="-1.57"
    upper="1.57"
    effort="1.0"
    velocity="1.0" />
</joint>

  <link name="gear_1">
  <inertial>
    <origin xyz="0 0 0.005" rpy="0 0 0" />
    <mass value="0.004" />
    <inertia
      ixx="5e-7" ixy="0.0" ixz="0.0"
      iyy="5e-7" iyz="0.0"
      izz="7e-7" />
  </inertial>

  <visual>
    <origin xyz="0 0 0" rpy="0 0 0" />
    <geometry>
      <mesh filename="package://ReadyRoboticArm_1/meshes/gear_1.STL" />
    </geometry>
    <material name="">
      <color rgba="0.7 0.7 0.7 1" />
    </material>
  </visual>

  <collision>
    <origin xyz="0 0 0" rpy="0 0 0" />
    <geometry>
      <mesh filename="package://ReadyRoboticArm_1/meshes/gear_1.STL" />
    </geometry>
  </collision>
</link>

<joint name="gear_joint_1" type="revolute">
  <origin xyz="0 0 0" rpy="0 0 0" />
  <parent link="link_5" />
  <child link="gear_1" />
  <axis xyz="0 0 1" />
  <limit lower="-1.5708" upper="1.5708" effort="0.3" velocity="1.5" />
</joint>


<link name="grip_1_left">
  <inertial>
    <origin xyz="0 0 0.025" rpy="0 0 0" />
    <mass value="0.006" />
    <inertia
      ixx="0.0000005" ixy="0.0" ixz="0.0"
      iyy="0.0000003" iyz="0.0"
      izz="0.0000008" />
  </inertial>

  <visual>
    <origin xyz="0 0 0" rpy="0 0 0" />
    <geometry>
      <mesh filename="package://ReadyRoboticArm_1/meshes/grip_1_left.STL" />
    </geometry>
    <material name="">
      <color rgba="0.792156862745098 0.819607843137255 0.933333333333333 1" />
    </material>
  </visual>

  <collision>
    <origin xyz="0 0 0" rpy="0 0 0" />
    <geometry>
      <mesh filename="package://ReadyRoboticArm_1/meshes/grip_1_left.STL" />
    </geometry>
  </collision>
</link>

  <joint name="grip_joint_1" type="revolute">
  <origin xyz="0 0 0" rpy="0 0 0" />
  <parent link="gear_1" />
  <child link="grip_1_left" />
  <axis xyz="0 0 1" />
  <mimic joint="gear_joint_1" multiplier="1.0" />
</joint>

<link name="connected_1_left">
  <inertial>
    <origin xyz="0 0 0.015" rpy="0 0 0"/>
    <mass value="0.0008"/>
    <inertia
      ixx="2e-8" ixy="0.0" ixz="0.0"
      iyy="1e-7" iyz="0.0"
      izz="1e-7"/>
  </inertial>

  <visual>
    <origin xyz="0 0 0" rpy="0 0 0"/>
    <geometry>
      <mesh filename="package://ReadyRoboticArm_1/meshes/connected_1_left.STL"/>
    </geometry>
    <material name="">
      <color rgba="0.792 0.819 0.933 1"/>
    </material>
  </visual>

  <collision>
    <origin xyz="0 0 0" rpy="0 0 0"/>
    <geometry>
      <mesh filename="package://ReadyRoboticArm_1/meshes/connected_1_left.STL"/>
    </geometry>
  </collision>
</link>

  <joint name="c_joint_left_1" type="revolute">
  <origin xyz="0 0 0" rpy="0 0 0"/>
  <parent link="link_5"/>
  <child link="connected_1_left"/>
  <axis xyz="0 0 1"/>
  <limit lower="-1.5708" upper="1.5708" effort="0.2" velocity="1.0"/>
</joint>

<link name="grip_2_left">
  <inertial>
    <origin xyz="0 0 0.02" rpy="0 0 0" />
    <mass value="0.0054" />
    <inertia
      ixx="1.6e-6" ixy="0.0" ixz="0.0"
      iyy="1.8e-7" iyz="0.0"
      izz="1.6e-6" />
  </inertial>

  <visual>
    <origin xyz="0 0 0" rpy="0 0 0" />
    <geometry>
      <mesh filename="package://ReadyRoboticArm_1/meshes/grip_2_left.STL" />
    </geometry>
    <material name="">
      <color rgba="0.792 0.819 0.933 1" />
    </material>
  </visual>

  <collision>
    <origin xyz="0 0 0" rpy="0 0 0" />
    <geometry>
      <mesh filename="package://ReadyRoboticArm_1/meshes/grip_2_left.STL" />
    </geometry>
  </collision>
</link>

  <joint name="grip_joint_2" type="revolute">
  <origin xyz="0 0 0" rpy="0 0 0" />
  <parent link="connected_1_left" />
  <child link="grip_2_left" />
  <axis xyz="0 0 1" />
  <limit lower="-1.57" upper="1.57" effort="0.2" velocity="1.0" />
</joint>

 <link name="connected_2_left">
  <inertial>
    <origin xyz="0 0 0.015" rpy="0 0 0"/>
    <mass value="0.0008"/>
    <inertia
      ixx="2e-8" ixy="0.0" ixz="0.0"
      iyy="1e-7" iyz="0.0"
      izz="1e-7"/>
  </inertial>

  <visual>
    <origin xyz="0 0 0" rpy="0 0 0"/>
    <geometry>
      <mesh filename="package://ReadyRoboticArm_1/meshes/connected_2_left.STL"/>
    </geometry>
    <material name="">
      <color rgba="0.792 0.819 0.933 1"/>
    </material>
  </visual>

  <collision>
    <origin xyz="0 0 0" rpy="0 0 0"/>
    <geometry>
      <mesh filename="package://ReadyRoboticArm_1/meshes/connected_2_left.STL"/>
    </geometry>
  </collision>
</link>

 <joint name="connected_joint_2_left" type="revolute">
  <origin xyz="0 0 0" rpy="0 0 0"/>
  <parent link="link_5"/>
  <child link="connected_2_left"/>
  <axis xyz="0 0 1"/>
  <limit lower="-1.5708" upper="1.5708" effort="0.2" velocity="1.0"/>
</joint>

  <link name="grip_3_left">
  <inertial>
    <origin xyz="0 0 0.02" rpy="0 0 0" />
    <mass value="0.0054" />
    <inertia
      ixx="1.6e-6" ixy="0.0" ixz="0.0"
      iyy="1.8e-7" iyz="0.0"
      izz="1.6e-6" />
  </inertial>

  <visual>
    <origin xyz="0 0 0" rpy="0 0 0" />
    <geometry>
      <mesh filename="package://ReadyRoboticArm_1/meshes/grip_3_left.STL" />
    </geometry>
    <material name="">
      <color rgba="0.792 0.819 0.933 1" />
    </material>
  </visual>

  <collision>
    <origin xyz="0 0 0" rpy="0 0 0" />
    <geometry>
      <mesh filename="package://ReadyRoboticArm_1/meshes/grip_3_left.STL" />
    </geometry>
  </collision>
</link>

 <joint name="grip_joint_3_left" type="revolute">
  <origin xyz="0 0 0" rpy="0 0 0" />
  <parent link="connected_2_left" />
  <child link="grip_3_left" />
  <axis xyz="0 0 1" />
  <limit lower="-1.5708" upper="1.5708" effort="0.2" velocity="1.0" />
</joint>

<link name="gear_2">
  <inertial>
    <origin xyz="0 0 0.005" rpy="0 0 0" />
    <mass value="0.004" />
    <inertia
      ixx="5e-7" ixy="0.0" ixz="0.0"
      iyy="5e-7" iyz="0.0"
      izz="7e-7" />
  </inertial>

  <visual>
    <origin xyz="0 0 0" rpy="0 0 0" />
    <geometry>
      <mesh filename="package://ReadyRoboticArm_1/meshes/gear_2.STL" />
    </geometry>
    <material name="">
      <color rgba="0.79215686 0.81960784 0.93333333 1" />
    </material>
  </visual>

  <collision>
    <origin xyz="0 0 0" rpy="0 0 0" />
    <geometry>
      <mesh filename="package://ReadyRoboticArm_1/meshes/gear_2.STL" />
    </geometry>
  </collision>
</link>

  <joint name="joint_gear_2" type="revolute">
  <origin xyz="0 0 0" rpy="0 0 0" />
  <parent link="link_5" />
  <child link="gear_2" />
  <axis xyz="0 0 1" />
  <mimic joint="gear_joint_1" multiplier="-1.0" />
</joint>

  <link name="grip_1_right">
  <inertial>
    <origin xyz="0 0 0.02" rpy="0 0 0" />
    <mass value="0.0054" />
    <inertia
      ixx="1.6e-6" ixy="0.0" ixz="0.0"
      iyy="1.8e-7" iyz="0.0"
      izz="1.6e-6" />
  </inertial>

  <visual>
    <origin xyz="0 0 0" rpy="0 0 0" />
    <geometry>
      <mesh filename="package://ReadyRoboticArm_1/meshes/grip_1_right.STL" />
    </geometry>
    <material name="">
      <color rgba="0.792 0.819 0.933 1" />
    </material>
  </visual>

  <collision>
    <origin xyz="0 0 0" rpy="0 0 0" />
    <geometry>
      <mesh filename="package://ReadyRoboticArm_1/meshes/grip_1_right.STL" />
    </geometry>
  </collision>
</link>

  <joint name="grip_joint_2" type="revolute">
  <origin xyz="0 0 0" rpy="0 0 0" />
  <parent link="gear_2" />
  <child link="grip_1_right" />
  <axis xyz="0 0 1" />
  <mimic joint="joint_gear_2" multiplier="1.0" />
</joint>

<link name="connection_1_right">
  <inertial>
    <origin xyz="0 0 0.015" rpy="0 0 0"/>
    <mass value="0.0008"/>
    <inertia
      ixx="2e-8" ixy="0.0" ixz="0.0"
      iyy="1e-7" iyz="0.0"
      izz="1e-7"/>
  </inertial>

  <visual>
    <origin xyz="0 0 0" rpy="0 0 0"/>
    <geometry>
      <mesh filename="package://ReadyRoboticArm_1/meshes/connection_1_right.STL"/>
    </geometry>
    <material name="">
      <color rgba="0.792 0.819 0.933 1"/>
    </material>
  </visual>

  <collision>
    <origin xyz="0 0 0" rpy="0 0 0"/>
    <geometry>
      <mesh filename="package://ReadyRoboticArm_1/meshes/connection_1_right.STL"/>
    </geometry>
  </collision>
</link>

<joint name="connection_joint_right" type="revolute">
  <origin xyz="0 0 0" rpy="0 0 0"/>
  <parent link="link_5"/>
  <child link="connection_1_right"/>
  <axis xyz="0 0 1"/>
  <limit lower="-1.5708" upper="1.5708" effort="0.2" velocity="1.0"/>
</joint>

 <link name="grip_2_right">
  <inertial>
    <origin xyz="0 0 0.02" rpy="0 0 0" />
    <mass value="0.0054" />
    <inertia
      ixx="1.6e-6" ixy="0.0" ixz="0.0"
      iyy="1.8e-7" iyz="0.0"
      izz="1.6e-6" />
  </inertial>

  <visual>
    <origin xyz="0 0 0" rpy="0 0 0" />
    <geometry>
      <mesh filename="package://ReadyRoboticArm_1/meshes/grip_2_right.STL" />
    </geometry>
    <material name="">
      <color rgba="0.792 0.819 0.933 1" />
    </material>
  </visual>

  <collision>
    <origin xyz="0 0 0" rpy="0 0 0" />
    <geometry>
      <mesh filename="package://ReadyRoboticArm_1/meshes/grip_2_right.STL" />
    </geometry>
  </collision>
</link>


 <joint name="grip_joint_2_right" type="revolute">
  <origin xyz="0 0 0" rpy="0 0 0"/>
  <parent link="connection_1_right"/>
  <child link="grip_2_right"/>
  <axis xyz="0 0 1"/>
  <limit lower="-1.5708" upper="1.5708" effort="0.2" velocity="1.0"/>
</joint>

<link name="connection_2_right">
  <inertial>
    <origin xyz="0 0 0.015" rpy="0 0 0"/>
    <mass value="0.0008"/>
    <inertia
      ixx="2e-8" ixy="0.0" ixz="0.0"
      iyy="1e-7" iyz="0.0"
      izz="1e-7"/>
  </inertial>

  <visual>
    <origin xyz="0 0 0" rpy="0 0 0"/>
    <geometry>
      <mesh filename="package://ReadyRoboticArm_1/meshes/connection_2_right.STL"/>
    </geometry>
    <material name="">
      <color rgba="0.792 0.819 0.933 1"/>
    </material>
  </visual>

  <collision>
    <origin xyz="0 0 0" rpy="0 0 0"/>
    <geometry>
      <mesh filename="package://ReadyRoboticArm_1/meshes/connection_2_right.STL"/>
    </geometry>
  </collision>
</link>

  <joint name="joint_connected_2_right" type="revolute">
  <origin xyz="0 0 0" rpy="0 0 0"/>
  <parent link="link_5"/>
  <child link="connection_2_right"/>
  <axis xyz="0 0 1"/>
  <limit lower="-1.5708" upper="1.5708" effort="0.2" velocity="1.0"/>
</joint>

  <link name="grip_3_right">
  <inertial>
    <origin xyz="0 0 0.02" rpy="0 0 0"/>
    <mass value="0.0054"/>
    <inertia
      ixx="1.6e-6" ixy="0.0" ixz="0.0"
      iyy="1.8e-7" iyz="0.0"
      izz="1.6e-6"/>
  </inertial>

  <visual>
    <origin xyz="0 0 0" rpy="0 0 0"/>
    <geometry>
      <mesh filename="package://ReadyRoboticArm_1/meshes/grip_3_right.STL"/>
    </geometry>
    <material name="">
      <color rgba="0.792 0.819 0.933 1"/>
    </material>
  </visual>

  <collision>
    <origin xyz="0 0 0" rpy="0 0 0"/>
    <geometry>
      <mesh filename="package://ReadyRoboticArm_1/meshes/grip_3_right.STL"/>
    </geometry>
  </collision>
</link>

  <joint name="grip_joint_3_right" type="revolute">
  <origin xyz="0 0 0" rpy="0 0 0"/>
  <parent link="connection_2_right"/>
  <child link="grip_3_right"/>
  <axis xyz="0 0 1"/>
  <mimic joint="grip_joint_3_left" multiplier="1.0"/>
</joint>
<!-- GAZEBO CONTROL PLUGIN -->
<gazebo>
  <plugin name="gazebo_ros_control" filename="libgazebo_ros_control.so">
    <robotNamespace>/</robotNamespace>
  </plugin>
</gazebo>

<!-- TRANSMISSIONS FOR ACTUATED JOINTS -->
<transmission name="joint_1_trans">
  <type>transmission_interface/SimpleTransmission</type>
  <joint name="joint_1">
    <hardwareInterface>hardware_interface/PositionJointInterface</hardwareInterface>
  </joint>
  <actuator name="joint_1_motor">
    <hardwareInterface>hardware_interface/PositionJointInterface</hardwareInterface>
    <mechanicalReduction>1</mechanicalReduction>
  </actuator>
</transmission>

<transmission name="joint_2_trans">
  <type>transmission_interface/SimpleTransmission</type>
  <joint name="joint_2">
    <hardwareInterface>hardware_interface/PositionJointInterface</hardwareInterface>
  </joint>
  <actuator name="joint_2_motor">
    <hardwareInterface>hardware_interface/PositionJointInterface</hardwareInterface>
    <mechanicalReduction>1</mechanicalReduction>
  </actuator>
</transmission>

<transmission name="joint_3_trans">
  <type>transmission_interface/SimpleTransmission</type>
  <joint name="joint_3">
    <hardwareInterface>hardware_interface/PositionJointInterface</hardwareInterface>
  </joint>
  <actuator name="joint_3_motor">
    <hardwareInterface>hardware_interface/PositionJointInterface</hardwareInterface>
    <mechanicalReduction>1</mechanicalReduction>
  </actuator>
</transmission>

<transmission name="joint_4_trans">
  <type>transmission_interface/SimpleTransmission</type>
  <joint name="joint_4">
    <hardwareInterface>hardware_interface/PositionJointInterface</hardwareInterface>
  </joint>
  <actuator name="joint_4_motor">
    <hardwareInterface>hardware_interface/PositionJointInterface</hardwareInterface>
    <mechanicalReduction>1</mechanicalReduction>
  </actuator>
</transmission>

<transmission name="joint_5_trans">
  <type>transmission_interface/SimpleTransmission</type>
  <joint name="joint_5">
    <hardwareInterface>hardware_interface/PositionJointInterface</hardwareInterface>
  </joint>
  <actuator name="joint_5_motor">
    <hardwareInterface>hardware_interface/PositionJointInterface</hardwareInterface>
    <mechanicalReduction>1</mechanicalReduction>
  </actuator>
</transmission>

<transmission name="gear_joint_1_trans">
  <type>transmission_interface/SimpleTransmission</type>
  <joint name="gear_joint_1">
    <hardwareInterface>hardware_interface/PositionJointInterface</hardwareInterface>
  </joint>
  <actuator name="gear_joint_1_motor">
    <hardwareInterface>hardware_interface/PositionJointInterface</hardwareInterface>
    <mechanicalReduction>1</mechanicalReduction>
  </actuator>
</transmission>

<transmission name="c_joint_left_1_trans">
  <type>transmission_interface/SimpleTransmission</type>
  <joint name="c_joint_left_1">
    <hardwareInterface>hardware_interface/PositionJointInterface</hardwareInterface>
  </joint>
  <actuator name="c_joint_left_1_motor">
    <hardwareInterface>hardware_interface/PositionJointInterface</hardwareInterface>
    <mechanicalReduction>1</mechanicalReduction>
  </actuator>
</transmission>

<!-- GAZEBO SELF COLLISION (OPTIONAL) -->
<gazebo reference="base_link">
  <selfCollide>true</selfCollide>
</gazebo>
<gazebo reference="link_1">
  <selfCollide>true</selfCollide>
</gazebo>
<gazebo reference="link_2">
  <selfCollide>true</selfCollide>
</gazebo>
<gazebo reference="link_3">
  <selfCollide>true</selfCollide>
</gazebo>
<gazebo reference="link_4">
  <selfCollide>true</selfCollide>
</gazebo>
<gazebo reference="link_5">
  <selfCollide>true</selfCollide>
</gazebo>


</robot>